{
    DataVersion: 3955,
    size: [5, 4, 5],
    data: [
        {pos: [0, 0, 0], state: "modernfoundry:seared_cobble"},
        {pos: [0, 0, 1], state: "modernfoundry:seared_cobble"},
        {pos: [0, 0, 2], state: "modernfoundry:seared_cobble"},
        {pos: [0, 0, 3], state: "modernfoundry:seared_cobble"},
        {pos: [0, 0, 4], state: "modernfoundry:seared_cobble"},
        {pos: [1, 0, 0], state: "modernfoundry:seared_cobble"},
        {pos: [1, 0, 1], state: "modernfoundry:seared_cobble"},
        {pos: [1, 0, 2], state: "modernfoundry:seared_cobble"},
        {pos: [1, 0, 3], state: "modernfoundry:seared_cobble"},
        {pos: [1, 0, 4], state: "modernfoundry:seared_cobble"},
        {pos: [2, 0, 0], state: "modernfoundry:seared_cobble"},
        {pos: [2, 0, 1], state: "modernfoundry:seared_cobble"},
        {pos: [2, 0, 2], state: "modernfoundry:seared_cobble"},
        {pos: [2, 0, 3], state: "modernfoundry:seared_cobble"},
        {pos: [2, 0, 4], state: "modernfoundry:seared_cobble"},
        {pos: [3, 0, 0], state: "modernfoundry:seared_cobble"},
        {pos: [3, 0, 1], state: "modernfoundry:seared_cobble"},
        {pos: [3, 0, 2], state: "modernfoundry:seared_cobble"},
        {pos: [3, 0, 3], state: "modernfoundry:seared_cobble"},
        {pos: [3, 0, 4], state: "modernfoundry:seared_cobble"},
        {pos: [4, 0, 0], state: "modernfoundry:seared_cobble"},
        {pos: [4, 0, 1], state: "modernfoundry:seared_cobble"},
        {pos: [4, 0, 2], state: "modernfoundry:seared_cobble"},
        {pos: [4, 0, 3], state: "modernfoundry:seared_cobble"},
        {pos: [4, 0, 4], state: "modernfoundry:seared_cobble"},
        {pos: [1, 1, 2], state: "modernfoundry:seared_bricks"},
        {pos: [2, 1, 2], state: "modernfoundry:seared_bricks"},
        {pos: [3, 1, 2], state: "modernfoundry:seared_bricks"},
        {pos: [1, 2, 2], state: "modernfoundry:seared_drain"},
        {pos: [2, 2, 2], state: "modernfoundry:seared_duct"},
        {pos: [3, 2, 2], state: "modernfoundry:seared_chute"},
        {pos: [1, 3, 2], state: "modernfoundry:seared_bricks"},
        {pos: [2, 3, 2], state: "modernfoundry:seared_bricks"},
        {pos: [3, 3, 2], state: "modernfoundry:seared_bricks"}
    ],
    entities: [],
    palette: [
        "modernfoundry:seared_cobble",
        "modernfoundry:seared_bricks",
        "modernfoundry:seared_drain",
        "modernfoundry:seared_duct",
        "modernfoundry:seared_chute"
    ]
}