{
    DataVersion: 3955,
    size: [5, 4, 5],
    data: [
        {pos: [0, 0, 0], state: "modernfoundry:seared_cobble"},
        {pos: [0, 0, 1], state: "modernfoundry:seared_cobble"},
        {pos: [0, 0, 2], state: "modernfoundry:seared_cobble"},
        {pos: [0, 0, 3], state: "modernfoundry:seared_cobble"},
        {pos: [0, 0, 4], state: "modernfoundry:seared_cobble"},
        {pos: [1, 0, 0], state: "modernfoundry:seared_cobble"},
        {pos: [1, 0, 1], state: "modernfoundry:seared_cobble"},
        {pos: [1, 0, 2], state: "modernfoundry:seared_cobble"},
        {pos: [1, 0, 3], state: "modernfoundry:seared_cobble"},
        {pos: [1, 0, 4], state: "modernfoundry:seared_cobble"},
        {pos: [2, 0, 0], state: "modernfoundry:seared_cobble"},
        {pos: [2, 0, 1], state: "modernfoundry:seared_cobble"},
        {pos: [2, 0, 2], state: "modernfoundry:seared_cobble"},
        {pos: [2, 0, 3], state: "modernfoundry:seared_cobble"},
        {pos: [2, 0, 4], state: "modernfoundry:seared_cobble"},
        {pos: [3, 0, 0], state: "modernfoundry:seared_cobble"},
        {pos: [3, 0, 1], state: "modernfoundry:seared_cobble"},
        {pos: [3, 0, 2], state: "modernfoundry:seared_cobble"},
        {pos: [3, 0, 3], state: "modernfoundry:seared_cobble"},
        {pos: [3, 0, 4], state: "modernfoundry:seared_cobble"},
        {pos: [4, 0, 0], state: "modernfoundry:seared_cobble"},
        {pos: [4, 0, 1], state: "modernfoundry:seared_cobble"},
        {pos: [4, 0, 2], state: "modernfoundry:seared_cobble"},
        {pos: [4, 0, 3], state: "modernfoundry:seared_cobble"},
        {pos: [4, 0, 4], state: "modernfoundry:seared_cobble"},
        {pos: [0, 1, 0], state: "modernfoundry:seared_bricks"},
        {pos: [0, 1, 1], state: "modernfoundry:seared_bricks"},
        {pos: [0, 1, 2], state: "modernfoundry:seared_bricks"},
        {pos: [0, 1, 3], state: "modernfoundry:seared_bricks"},
        {pos: [0, 1, 4], state: "modernfoundry:seared_bricks"},
        {pos: [1, 1, 0], state: "modernfoundry:seared_bricks"},
        {pos: [1, 1, 1], state: "modernfoundry:seared_bricks"},
        {pos: [1, 1, 2], state: "modernfoundry:seared_bricks"},
        {pos: [1, 1, 3], state: "modernfoundry:seared_bricks"},
        {pos: [1, 1, 4], state: "modernfoundry:seared_bricks"},
        {pos: [2, 1, 0], state: "modernfoundry:seared_bricks"},
        {pos: [2, 1, 1], state: "modernfoundry:seared_bricks"},
        {pos: [2, 1, 2], state: "modernfoundry:seared_bricks"},
        {pos: [2, 1, 3], state: "modernfoundry:seared_bricks"},
        {pos: [2, 1, 4], state: "modernfoundry:seared_bricks"},
        {pos: [3, 1, 0], state: "modernfoundry:seared_bricks"},
        {pos: [3, 1, 1], state: "modernfoundry:seared_bricks"},
        {pos: [3, 1, 2], state: "modernfoundry:seared_bricks"},
        {pos: [3, 1, 3], state: "modernfoundry:seared_bricks"},
        {pos: [3, 1, 4], state: "modernfoundry:seared_bricks"},
        {pos: [4, 1, 0], state: "modernfoundry:seared_bricks"},
        {pos: [4, 1, 1], state: "modernfoundry:seared_bricks"},
        {pos: [4, 1, 2], state: "modernfoundry:seared_bricks"},
        {pos: [4, 1, 3], state: "modernfoundry:seared_bricks"},
        {pos: [4, 1, 4], state: "modernfoundry:seared_bricks"},
        {pos: [0, 2, 0], state: "modernfoundry:seared_bricks"},
        {pos: [0, 2, 1], state: "modernfoundry:seared_bricks"},
        {pos: [0, 2, 2], state: "modernfoundry:seared_fuel_tank"},
        {pos: [0, 2, 3], state: "modernfoundry:seared_bricks"},
        {pos: [0, 2, 4], state: "modernfoundry:seared_bricks"},
        {pos: [1, 2, 0], state: "modernfoundry:seared_bricks"},
        {pos: [1, 2, 4], state: "modernfoundry:seared_bricks"},
        {pos: [2, 2, 0], state: "modernfoundry:smeltery_controller"},
        {pos: [2, 2, 4], state: "modernfoundry:seared_glass"},
        {pos: [3, 2, 0], state: "modernfoundry:seared_bricks"},
        {pos: [3, 2, 4], state: "modernfoundry:seared_bricks"},
        {pos: [4, 2, 0], state: "modernfoundry:seared_bricks"},
        {pos: [4, 2, 1], state: "modernfoundry:seared_bricks"},
        {pos: [4, 2, 2], state: "modernfoundry:seared_drain"},
        {pos: [4, 2, 3], state: "modernfoundry:seared_bricks"},
        {pos: [4, 2, 4], state: "modernfoundry:seared_bricks"},
        {pos: [0, 3, 0], state: "modernfoundry:seared_bricks"},
        {pos: [0, 3, 1], state: "modernfoundry:seared_bricks"},
        {pos: [0, 3, 2], state: "modernfoundry:seared_bricks"},
        {pos: [0, 3, 3], state: "modernfoundry:seared_bricks"},
        {pos: [0, 3, 4], state: "modernfoundry:seared_bricks"},
        {pos: [1, 3, 0], state: "modernfoundry:seared_bricks"},
        {pos: [1, 3, 4], state: "modernfoundry:seared_bricks"},
        {pos: [2, 3, 0], state: "modernfoundry:seared_bricks"},
        {pos: [2, 3, 4], state: "modernfoundry:seared_bricks"},
        {pos: [3, 3, 0], state: "modernfoundry:seared_bricks"},
        {pos: [3, 3, 4], state: "modernfoundry:seared_bricks"},
        {pos: [4, 3, 0], state: "modernfoundry:seared_bricks"},
        {pos: [4, 3, 1], state: "modernfoundry:seared_bricks"},
        {pos: [4, 3, 2], state: "modernfoundry:seared_bricks"},
        {pos: [4, 3, 3], state: "modernfoundry:seared_bricks"},
        {pos: [4, 3, 4], state: "modernfoundry:seared_bricks"}
    ],
    entities: [],
    palette: [
        "modernfoundry:seared_cobble",
        "modernfoundry:seared_bricks",
        "modernfoundry:smeltery_controller",
        "modernfoundry:seared_glass",
        "modernfoundry:seared_fuel_tank",
        "modernfoundry:seared_drain"
    ]
}